2024-10-16 19:42:19,054 INFO    MainThread:40184 [wandb_setup.py:_flush():79] Current SDK version is 0.18.3
2024-10-16 19:42:19,055 INFO    MainThread:40184 [wandb_setup.py:_flush():79] Configure stats pid to 40184
2024-10-16 19:42:19,055 INFO    MainThread:40184 [wandb_setup.py:_flush():79] Loading settings from C:\Users\saura\.config\wandb\settings
2024-10-16 19:42:19,055 INFO    MainThread:40184 [wandb_setup.py:_flush():79] Loading settings from C:\all_projects\learning_mlops\learning_mlops\learning_mlops\outputs\2024-10-16\19-42-00\wandb\settings
2024-10-16 19:42:19,055 INFO    MainThread:40184 [wandb_setup.py:_flush():79] Loading settings from environment variables: {}
2024-10-16 19:42:19,055 INFO    MainThread:40184 [wandb_setup.py:_flush():79] Applying setup settings: {'mode': None, '_disable_service': None}
2024-10-16 19:42:19,057 WARNING MainThread:40184 [wandb_setup.py:_flush():79] Could not find program at train.py
2024-10-16 19:42:19,057 INFO    MainThread:40184 [wandb_setup.py:_flush():79] Inferring run settings from compute environment: {'program_relpath': None, 'program': 'train.py'}
2024-10-16 19:42:19,057 INFO    MainThread:40184 [wandb_setup.py:_flush():79] Applying login settings: {}
2024-10-16 19:42:19,057 INFO    MainThread:40184 [wandb_init.py:_log_setup():532] Logging user logs to C:\all_projects\learning_mlops\learning_mlops\learning_mlops\outputs\2024-10-16\19-42-00\wandb\run-20241016_194219-ptarp2m2\logs\debug.log
2024-10-16 19:42:19,057 INFO    MainThread:40184 [wandb_init.py:_log_setup():533] Logging internal logs to C:\all_projects\learning_mlops\learning_mlops\learning_mlops\outputs\2024-10-16\19-42-00\wandb\run-20241016_194219-ptarp2m2\logs\debug-internal.log
2024-10-16 19:42:19,057 INFO    MainThread:40184 [wandb_init.py:init():617] calling init triggers
2024-10-16 19:42:19,058 INFO    MainThread:40184 [wandb_init.py:init():624] wandb.init called with sweep_config: {}
config: {}
2024-10-16 19:42:19,058 INFO    MainThread:40184 [wandb_init.py:init():667] starting backend
2024-10-16 19:42:19,058 INFO    MainThread:40184 [wandb_init.py:init():671] sending inform_init request
2024-10-16 19:42:19,072 INFO    MainThread:40184 [backend.py:_multiprocessing_setup():104] multiprocessing start_methods=spawn, using: spawn
2024-10-16 19:42:19,073 INFO    MainThread:40184 [wandb_init.py:init():684] backend started and connected
2024-10-16 19:42:19,104 INFO    MainThread:40184 [wandb_init.py:init():779] updated telemetry
2024-10-16 19:42:19,199 INFO    MainThread:40184 [wandb_init.py:init():812] communicating run to backend with 90.0 second timeout
2024-10-16 19:42:20,636 ERROR   MainThread:40184 [wandb_init.py:init():838] encountered error: failed to upsert bucket: returned error 403 Forbidden: {"errors":[{"message":"permission denied","path":["upsertBucket"],"extensions":{"code":"PERMISSION_ERROR"}}],"data":{"upsertBucket":null}}
2024-10-16 19:42:20,637 ERROR   MainThread:40184 [wandb_init.py:init():1262] error in wandb.init()
Traceback (most recent call last):
  File "C:\Users\saura\.conda\envs\project-setup\lib\site-packages\wandb\sdk\wandb_init.py", line 1252, in init
    return wi.init()
  File "C:\Users\saura\.conda\envs\project-setup\lib\site-packages\wandb\sdk\wandb_init.py", line 844, in init
    raise error
wandb.errors.errors.CommError: failed to upsert bucket: returned error 403 Forbidden: {"errors":[{"message":"permission denied","path":["upsertBucket"],"extensions":{"code":"PERMISSION_ERROR"}}],"data":{"upsertBucket":null}}
2024-10-16 19:42:23,299 WARNING MsgRouterThr:40184 [router.py:message_loop():77] message_loop has been closed
